Workbook
Name Год: Анкета!$C$12
Name Фамилия: Анкета!$C$3
Name ОВД: Анкета!$C$13
Name ОВЗ: Анкета!$C$14

Sheet Как_заполнять
A1: Как пользоваться журналом и рапортом
A3: Что это
A4: Книга повторяет официальный журнал из приложения № 7 к приказу Министра обороны РФ от 30.10.2015 № 660 (п. 25 Порядка) и отдельно ведёт боевое дежурство в сутках (п. 3 ст. 11 закона № 76-ФЗ и п. 5 приложения № 2 к Положению о порядке прохождения военной службы).
A5: Жёлтые ячейки
A6: Заполняете только их. Серые / голубые ячейки считаются сами — их не затирайте.
A7: 1. Анкета
A8: Впишите фамилию, звание, должность, в/ч, командира, оклады и год. Фамилия из анкеты сразу попадает в рапорт.
A9: 2. Журнал_день — ваш рабочий журнал
A10: Это повседневный учёт на каждый день года. Ставьте 1 в колонке «БД», если стояли на боевом дежурстве; 1 в «Наряд», если суточный наряд. Сверхурочные часы в рабочие дни — в графу «Сверхурочно, ч». Часы в выходной или праздник — в графу «Выходной/праздник, ч». Если дали отгул — часы в «Отдых дан, ч» или сутки в «К отпуску, сут».
A11: 3. Журнал_660 — как в части
A12: Это та самая официальная форма на неделю: графы 1–13, подпись военнослужащего, подпись командира подразделения. Выберите номер недели — часы подтянутся из Журнал_день. Можно дописать сослуживцев (журнал в части ведётся на подразделение).
A13: Важно про журнал 660
... A24: В журнале на 2026 год для примера отмечено 30 суток БД (1–30 января). Замените на свои отметки: должно получиться 20 суток отдыха.

Sheet Анкета
A1: Сведения о военнослужащем — попадают в журнал и в рапорт
A2: Реквизит | B2: Заполните жёлтое | C2: Значение
A3: Фамилия | C3: Петров
A4: Имя | C4: Пётр
A5: Отчество | C5: Петрович
A6: Воинское звание | C6: сержант
A7: Воинская должность | C7: командир отделения
A8: Подразделение | C8: 1 мсв 2 мср
A9: Войсковая часть | C9: 00000
A10: Командир части (звание) | C10: полковник
A11: Командир части (инициал и фамилия) | C11: И.И. Иванов
A12: Год учёта | C12: 2026
A13: Оклад по воинской должности, руб. | C13: 25000
A14: Оклад по воинскому званию, руб. | C14: 12000
A15: Продолжительность служебного дня, ч | C15: 8
A16: Номер недели для печати журнала 660 | C16: 1
A18: Служебные поля (не трогать)
A19: ФИО полностью | B19: =TRIM(C3&" "&C4&" "&C5)
A20: ФИО в рапорте (род. падеж — правьте при необходимости) | B20: =C3&"а "&LEFT(C4,1)&"."&LEFT(C5,1)&"."
A21: Кому рапорт | B21: ="Командиру войсковой части "&C9&" "&C10&"у "&C11
A22: От кого | B22: ="от "&C7&" "&C6&"а "&C3&"а "&LEFT(C4,1)&"."&LEFT(C5,1)&"."
A23: Оклады вместе | B23: =C13+C14
A24: 1/30 окладов | B24: =C23/30
A26: Родительный падеж в строке 20 проверьте сами: «Петрова П.П.» обычно верно, для фамилий на -о, -ых, -ко поправьте вручную.
A28: Подсказка по окладам
A29: Компенсация по приказу МО РФ № 80 считается только из двух окладов (должность + звание), без надбавок, премии и районного коэффициента. Берите цифры из расчётного листка.

Sheet Журнал_день
A1: ЕЖЕДНЕВНЫЙ УЧЁТ СЛУЖЕБНОГО ВРЕМЕНИ — заполняется на каждого военнослужащего. Жёлтое — ваши отметки. 1 = заступил. Часы — числом.
A2: =CONCATENATE("Военнослужащий: ",Анкета!C6," ",Анкета!B19," | ",Анкета!C7," | в/ч ",Анкета!C9," | год ",Анкета!C12)
A3: БД и наряд отмечайте единицей. Сверхурочка журнала 660 — только часы (графа 5 — рабочие дни, графа 6 — выходные/праздники). Боевое дежурство в часы 660 не переводите: оно идёт в лист «БД_сутки».
A4: № | B4: Дата | C4: День недели | D4: Неделя | E4: Месяц | F4: Вид дня | G4: БД (1) | H4: Наряд (1) | I4: Сверхурочно, ч (гр. 5) | J4: Выходной/ праздник, ч (гр. 6) | K4: Отдых дан, ч (гр. 9) | L4: К отпуску, сут (гр. 11) | M4: Примечание (приказ, график)
G5: БД | H5: наряд | I5: 5 | J5: 6 | K5: 9 | L5: 11
A6: 1 | B6: =IF(DATE(Анкета!$C$12,1,1)+0>DATE(Анкета!$C$12,12,31),"",DATE(Анкета!$C$12,1,1)+0) | C6: =IF(B6="","",CHOOSE(WEEKDAY(B6,2),"понедельник","вторник","среда","четверг","пятница","суббота","воскресенье")) | D6: =IF(B6="","",WEEKNUM(B6,21)) | E6: =IF(B6="","",MONTH(B6)) | F6: =IF(B6="","",IF(WEEKDAY(B6,2)>=6,"вых","раб")) | G6: 1
A7: 2 | B7: =IF(DATE(Анкета!$C$12,1,1)+1>DATE(Анкета!$C$12,12,31),"",DATE(Анкета!$C$12,1,1)+1) | C7: =IF(B7="","",CHOOSE(WEEKDAY(B7,2),"понедельник","вторник","среда","четверг","пятница","суббота","воскресенье")) | D7: =IF(B7="","",WEEKNUM(B7,21)) | E7: =IF(B7="","",MONTH(B7)) | F7: =IF(B7="","",IF(WEEKDAY(B7,2)>=6,"вых","раб")) | G7: 1
A8: 3 | B8: =IF(DATE(Анкета!$C$12,1,1)+2>DATE(Анкета!$C$12,12,31),"",DATE(Анкета!$C$12,1,1)+2) | C8: =IF(B8="","",CHOOSE(WEEKDAY(B8,2),"понедельник","вторник","среда","четверг","пятница","суббота","воскресенье")) | D8: =IF(B8="","",WEEKNUM(B8,21)) | E8: =IF(B8="","",MONTH(B8)) | F8: =IF(B8="","",IF(WEEKDAY(B8,2)>=6,"вых","раб")) | G8: 1
A9: 4 | B9: =IF(DATE(Анкета!$C$12,1,1)+3>DATE(Анкета!$C$12,12,31),"",DATE(Анкета!$C$12,1,1)+3) | C9: =IF(B9="","",CHOOSE(WEEKDAY(B9,2),"понедельник","вторник","среда","четверг","пятница","суббота","воскресенье")) | D9: =IF(B9="","",WEEKNUM(B9,21)) | E9: =IF(B9="","",MONTH(B9)) | F9: =IF(B9="","",IF(WEEKDAY(B9,2)>=6,"вых","раб")) | G9: 1
A10: 5 | B10: =IF(DATE(Анкета!$C$12,1,1)+4>DATE(Анкета!$C$12,12,31),"",DATE(Анкета!$C$12,1,1)+4) | C10: =IF(B10="","",CHOOSE(WEEKDAY(B10,2),"понедельник","вторник","среда","четверг","пятница","суббота","воскресенье")) | D10: =IF(B10="","",WEEKNUM(B10,21)) | E10: =IF(B10="","",MONTH(B10)) | F10: =IF(B10="","",IF(WEEKDAY(B10,2)>=6,"вых","раб")) | G10: 1
A11: 6 | B11: =IF(DATE(Анкета!$C$12,1,1)+5>DATE(Анкета!$C$12,12,31),"",DATE(Анкета!$C$12,1,1)+5) | C11: =IF(B11="","",CHOOSE(WEEKDAY(B11,2),"понедельник","вторник","среда","четверг","пятница","суббота","воскресенье")) | D11: =IF(B11="","",WEEKNUM(B11,21)) | E11: =IF(B11="","",MONTH(B11)) | F11: =IF(B11="","",IF(WEEKDAY(B11,2)>=6,"вых","раб")) | G11: 1
A12: 7 | B12: =IF(DATE(Анкета!$C$12,1,1)+6>DATE(Анкета!$C$12,12,31),"",DATE(Анкета!$C$12,1,1)+6) | C12: =IF(B12="","",CHOOSE(WEEKDAY(B12,2),"понедельник","вторник","среда","четверг","пятница","суббота","воскресенье")) | D12: =IF(B12="","",WEEKNUM(B12,21)) | E12: =IF(B12="","",MONTH(B12)) | F12: =IF(B12="","",IF(WEEKDAY(B12,2)>=6,"вых","раб")) | G12: 1
A13: 8 | B13: =IF(DATE(Анкета!$C$12,1,1)+7>DATE(Анкета!$C$12,12,31),"",DATE(Анкета!$C$12,1,1)+7) | C13: =IF(B13="","",CHOOSE(WEEKDAY(B13,2),"понедельник","вторник","среда","четверг","пятница","суббота","воскресенье")) | D13: =IF(B13="","",WEEKNUM(B13,21)) | E13: =IF(B13="","",MONTH(B13)) | F13: =IF(B13="","",IF(WEEKDAY(B13,2)>=6,"вых","раб")) | G13: 1
A14: 9 | B14: =IF(DATE(Анкета!$C$12,1,1)+8>DATE(Анкета!$C$12,12,31),"",DATE(Анкета!$C$12,1,1)+8) | C14: =IF(B14="","",CHOOSE(WEEKDAY(B14,2),"понедельник","вторник","среда","четверг","пятница","суббота","воскресенье")) | D14: =IF(B14="","",WEEKNUM(B14,21)) | E14: =IF(B14="","",MONTH(B14)) | F14: =IF(B14="","",IF(WEEKDAY(B14,2)>=6,"вых","раб")) | G14: 1
A15: 10 | B15: =IF(DATE(Анкета!$C$12,1,1)+9>DATE(Анкета!$C$12,12,31),"",DATE(Анкета!$C$12,1,1)+9) | C15: =IF(B15="","",CHOOSE(WEEKDAY(B15,2),"понедельник","вторник","среда","четверг","пятница","суббота","воскресенье")) | D15: =IF(B15="","",WEEKNUM(B15,21)) | E15: =IF(B15="","",MONTH(B15)) | F15: =IF(B15="","",IF(WEEKDAY(B15,2)>=6,"вых","раб")) | G15: 1
A16: 11 | B16: =IF(DATE(Анкета!$C$12,1,1)+10>DATE(Анкета!$C$12,12,31),"",DATE(Анкета!$C$12,1,1)+10) | C16: =IF(B16="","",CHOOSE(WEEKDAY(B16,2),"понедельник","вторник","среда","четверг","пятница","суббота","воскресенье")) | D16: =IF(B16="","",WEEKNUM(B16,21)) | E16: =IF(B16="","",MONTH(B16)) | F16: =IF(B16="","",IF(WEEKDAY(B16,2)>=6,"вых","раб")) | G16: 1
A17: 12 | B17: =IF(DATE(Анкета!$C$12,1,1)+11>DATE(Анкета!$C$12,12,31),"",DATE(Анкета!$C$12,1,1)+11) | C17: =IF(B17="","",CHOOSE(WEEKDAY(B17,2),"понедельник","вторник","среда","четверг","пятница","суббота","воскресенье")) | D17: =IF(B17="","",WEEKNUM(B17,21)) | E17: =IF(B17="","",MONTH(B17)) | F17: =IF(B17="","",IF(WEEKDAY(B17,2)>=6,"вых","раб")) | G17: 1
A18: 13 | B18: =IF(DATE(Анкета!$C$12,1,1)+12>DATE(Анкета!$C$12,12,31),"",DATE(Анкета!$C$12,1,1)+12) | C18: =IF(B18="","",CHOOSE(WEEKDAY(B18,2),"понедельник","вторник","среда","четверг","пятница","суббота","воскресенье")) | D18: =IF(B18="","",WEEKNUM(B18,21)) | E18: =IF(B18="","",MONTH(B18)) | F18: =IF(B18="","",IF(WEEKDAY(B18,2)>=6,"вых","раб")) | G18: 1
A19: 14 | B19: =IF(DATE(Анкета!$C$12,1,1)+13>DATE(Анкета!$C$12,12,31),"",DATE(Анкета!$C$12,1,1)+13) | C19: =IF(B19="","",CHOOSE(WEEKDAY(B19,2),"понедельник","вторник","среда","четверг","пятница","суббота","воскресенье")) | D19: =IF(B19="","",WEEKNUM(B19,21)) | E19: =IF(B19="","",MONTH(B19)) | F19: =IF(B19="","",IF(WEEKDAY(B19,2)>=6,"вых","раб")) | G19: 1
A20: 15 | B20: =IF(DATE(Анкета!$C$12,1,1)+14>DATE(Анкета!$C$12,12,31),"",DATE(Анкета!$C$12,1,1)+14) | C20: =IF(B20="","",CHOOSE(WEEKDAY(B20,2),"понедельник","вторник","среда","четверг","пятница","суббота","воскресенье")) | D20: =IF(B20="","",WEEKNUM(B20,21)) | E20: =IF(B20="","",MONTH(B20)) | F20: =IF(B20="","",IF(WEEKDAY(B20,2)>=6,"вых","раб")) | G20: 1
A21: 16 | B21: =IF(DATE(Анкета!$C$12,1,1)+15>DATE(Анкета!$C$12,12,31),"",DATE(Анкета!$C$12,1,1)+15) | C21: =IF(B21="","",CHOOSE(WEEKDAY(B21,2),"понедельник","вторник","среда","четверг","пятница","суббота","воскресенье")) | D21: =IF(B21="","",WEEKNUM(B21,21)) | E21: =IF(B21="","",MONTH(B21)) | F21: =IF(B21="","",IF(WEEKDAY(B21,2)>=6,"вых","раб")) | G21: 1
A22: 17 | B22: =IF(DATE(Анкета!$C$12,1,1)+16>DATE(Анкета!$C$12,12,31),"",DATE(Анкета!$C$12,1,1)+16) | C22: =IF(B22="","",CHOOSE(WEEKDAY(B22,2),"понедельник","вторник","среда","четверг","пятница","суббота","воскресенье")) | D22: =IF(B22="","",WEEKNUM(B22,21)) | E22: =IF(B22="","",MONTH(B22)) | F22: =IF(B22="","",IF(WEEKDAY(B22,2)>=6,"вых","раб")) | G22: 1
A23: 18 | B23: =IF(DATE(Анкета!$C$12,1,1)+17>DATE(Анкета!$C$12,12,31),"",DATE(Анкета!$C$12,1,1)+17) | C23: =IF(B23="","",CHOOSE(WEEKDAY(B23,2),"понедельник","вторник","среда","четверг","пятница","суббота","воскресенье")) | D23: =IF(B23="","",WEEKNUM(B23,21)) | E23: =IF(B23="","",MONTH(B23)) | F23: =IF(B23="","",IF(WEEKDAY(B23,2)>=6,"вых","раб")) | G23: 1
A24: 19 | B24: =IF(DATE(Анкета!$C$12,1,1)+18>DATE(Анкета!$C$12,12,31),"",DATE(Анкета!$C$12,1,1)+18) | C24: =IF(B24="","",CHOOSE(WEEKDAY(B24,2),"понедельник","вторник","среда","четверг","пятница","суббота","воскресенье")) | D24: =IF(B24="","",WEEKNUM(B24,21)) | E24: =IF(B24="","",MONTH(B24)) | F24: =IF(B24="","",IF(WEEKDAY(B24,2)>=6,"вых","раб")) | G24: 1
A25: 20 | B25: =IF(DATE(Анкета!$C$12,1,1)+19>DATE(Анкета!$C$12,12,31),"",DATE(Анкета!$C$12,1,1)+19) | C25: =IF(B25="","",CHOOSE(WEEKDAY(B25,2),"понедельник","вторник","среда","четверг","пятница","суббота","воскресенье")) | D25: =IF(B25="","",WEEKNUM(B25,21)) | E25: =IF(B25="","",MONTH(B25)) | F25: =IF(B25="","",IF(WEEKDAY(B25,2)>=6,"вых","раб")) | G25: 1
A26: 21 | B26: =IF(DATE(Анкета!$C$12,1,1)+20>DATE(Анкета!$C$12,12,31),"",DATE(Анкета!$C$12,1,1)+20) | C26: =IF(B26="","",CHOOSE(WEEKDAY(B26,2),"понедельник","вторник","среда","четверг","пятница","суббота","воскресенье")) | D26: =IF(B26="","",WEEKNUM(B26,21)) | E26: =IF(B26="","",MONTH(B26)) | F26: =IF(B26="","",IF(WEEKDAY(B26,2)>=6,"вых","раб")) | G26: 1
A27: 22 | B27: =IF(DATE(Анкета!$C$12,1,1)+21>DATE(Анкета!$C$12,12,31),"",DATE(Анкета!$C$12,1,1)+21) | C27: =IF(B27="","",CHOOSE(WEEKDAY(B27,2),"понедельник","вторник","среда","четверг","пятница","суббота","воскресенье")) | D27: =IF(B27="","",WEEKNUM(B27,21)) | E27: =IF(B27="","",MONTH(B27)) | F27: =IF(B27="","",IF(WEEKDAY(B27,2)>=6,"вых","раб")) | G27: 1
A28: 23 | B28: =IF(DATE(Анкета!$C$12,1,1)+22>DATE(Анкета!$C$12,12,31),"",DATE(Анкета!$C$12,1,1)+22) | C28: =IF(B28="","",CHOOSE(WEEKDAY(B28,2),"понедельник","вторник","среда","четверг","пятница","суббота","воскресенье")) | D28: =IF(B28="","",WEEKNUM(B28,21)) | E28: =IF(B28="","",MONTH(B28)) | F28: =IF(B28="","",IF(WEEKDAY(B28,2)>=6,"вых","раб")) | G28: 1
A29: 24 | B29: =IF(DATE(Анкета!$C$12,1,1)+23>DATE(Анкета!$C$12,12,31),"",DATE(Анкета!$C$12,1,1)+23) | C29: =IF(B29="","",CHOOSE(WEEKDAY(B29,2),"понедельник","вторник","среда","четверг","пятница","суббота","воскресенье")) | D29: =IF(B29="","",WEEKNUM(B29,21)) | E29: =IF(B29="","",MONTH(B29)) | F29: =IF(B29="","",IF(WEEKDAY(B29,2)>=6,"вых","раб")) | G29: 1
A30: 25 | B30: =IF(DATE(Анкета!$C$12,1,1)+24>DATE(Анкета!$C$12,12,31),"",DATE(Анкета!$C$12,1,1)+24) | C30: =IF(B30="","",CHOOSE(WEEKDAY(B30,2),"понедельник","вторник","среда","четверг","пятница","суббота","воскресенье")) | D30: =IF(B30="","",WEEKNUM(B30,21)) | E30: =IF(B30="","",MONTH(B30)) | F30: =IF(B30="","",IF(WEEKDAY(B30,2)>=6,"вых","раб")) | G30: 1
A31: 26 | B31: =IF(DATE(Анкета!$C$12,1,1)+25>DATE(Анкета!$C$12,12,31),"",DATE(Анкета!$C$12,1,1)+25) | C31: =IF(B31="","",CHOOSE(WEEKDAY(B31,2),"понедельник","вторник","среда","четверг","пятница","суббота","воскресенье")) | D31: =IF(B31="","",WEEKNUM(B31,21)) | E31: =IF(B31="","",MONTH(B31)) | F31: =IF(B31="","",IF(WEEKDAY(B31,2)>=6,"вых","раб")) | G31: 1
A32: 27 | B32: =IF(DATE(Анкета!$C$12,1,1)+26>DATE(Анкета!$C$12,12,31),"",DATE(Анкета!$C$12,1,1)+26) | C32: =IF(B32="","",CHOOSE(WEEKDAY(B32,2),"понедельник","вторник","среда","четверг","пятница","суббота","воскресенье")) | D32: =IF(B32="","",WEEKNUM(B32,21)) | E32: =IF(B32="","",MONTH(B32)) | F32: =IF(B32="","",IF(WEEKDAY(B32,2)>=6,"вых","раб")) | G32: 1
A33: 28 | B33: =IF(DATE(Анкета!$C$12,1,1)+27>DATE(Анкета!$C$12,12,31),"",DATE(Анкета!$C$12,1,1)+27) | C33: =IF(B33="","",CHOOSE(WEEKDAY(B33,2),"понедельник","вторник","среда","четверг","пятница","суббота","воскресенье")) | D33: =IF(B33="","",WEEKNUM(B33,21)) | E33: =IF(B33="","",MONTH(B33)) | F33: =IF(B33="","",IF(WEEKDAY(B33,2)>=6,"вых","раб")) | G33: 1
A34: 29 | B34: =IF(DATE(Анкета!$C$12,1,1)+28>DATE(Анкета!$C$12,12,31),"",DATE(Анкета!$C$12,1,1)+28) | C34: =IF(B34="","",CHOOSE(WEEKDAY(B34,2),"понедельник","вторник","среда","четверг","пятница","суббота","воскресенье")) | D34: =IF(B34="","",WEEKNUM(B34,21)) | E34: =IF(B34="","",MONTH(B34)) | F34: =IF(B34="","",IF(WEEKDAY(B34,2)>=6,"вых","раб")) | G34: 1
A35: 30 | B35: =IF(DATE(Анкета!$C$12,1,1)+29>DATE(Анкета!$C$12,12,31),"",DATE(Анкета!$C$12,1,1)+29) | C35: =IF(B35="","",CHOOSE(WEEKDAY(B35,2),"понедельник","вторник","среда","четверг","пятница","суббота","воскресенье")) | D35: =IF(B35="","",WEEKNUM(B35,21)) | E35: =IF(B35="","",MONTH(B35)) | F35: =IF(B35="","",IF(WEEKDAY(B35,2)>=6,"вых","раб")) | G35: 1
A36: 31 | B36: =IF(DATE(Анкета!$C$12,1,1)+30>DATE(Анкета!$C$12,12,31),"",DATE(Анкета!$C$12,1,1)+30) | C36: =IF(B36="","",CHOOSE(WEEKDAY(B36,2),"понедельник","вторник","среда","четверг","пятница","суббота","воскресенье")) | D36: =IF(B36="","",WEEKNUM(B36,21)) | E36: =IF(B36="","",MONTH(B36)) | F36: =IF(B36="","",IF(WEEKDAY(B36,2)>=6,"вых","раб"))
A37: 32 | B37: =IF(DATE(Анкета!$C$12,1,1)+31>DATE(Анкета!$C$12,12,31),"",DATE(Анкета!$C$12,1,1)+31) | C37: =IF(B37="","",CHOOSE(WEEKDAY(B37,2),"понедельник","вторник","среда","четверг","пятница","суббота","воскресенье")) | D37: =IF(B37="","",WEEKNUM(B37,21)) | E37: =IF(B37="","",MONTH(B37)) | F37: =IF(B37="","",IF(WEEKDAY(B37,2)>=6,"вых","раб"))
A38: 33 | B38: =IF(DATE(Анкета!$C$12,1,1)+32>DATE(Анкета!$C$12,12,31),"",DATE(Анкета!$C$12,1,1)+32) | C38: =IF(B38="","",CHOOSE(WEEKDAY(B38,2),"понедельник","вторник","среда","четверг","пятница","суббота","воскресенье")) | D38: =IF(B38="","",WEEKNUM(B38,21)) | E38: =IF(B38="","",MONTH(B38)) | F38: =IF(B38="","",IF(WEEKDAY(B38,2)>=6,"вых","раб"))
A39: 34 | B39: =IF(DATE(Анкета!$C$12,1,1)+33>DATE(Анкета!$C$12,12,31),"",DATE(Анкета!$C$12,1,1)+33) | C39: =IF(B39="","",CHOOSE(WEEKDAY(B39,2),"понедельник","вторник","среда","четверг","пятница","суббота","воскресенье")) | D39: =IF(B39="","",WEEKNUM(B39,21)) | E39: =IF(B39="","",MONTH(B39)) | F39: =IF(B39="","",IF(WEEKDAY(B39,2)>=6,"вых","раб"))
A40: 35 | B40: =IF(DATE(Анкета!$C$12,1,1)+34>DATE(Анкета!$C$12,12,31),"",DATE(Анкета!$C$12,1,1)+34) | C40: =IF(B40="","",CHOOSE(WEEKDAY(B40,2),"понедельник","вторник","среда","четверг","пятница","суббота","воскресенье")) | D40: =IF(B40="","",WEEKNUM(B40,21)) | E40: =IF(B40="","",MONTH(B40)) | F40: =IF(B40="","",IF(WEEKDAY(B40,2)>=6,"вых","раб"))
...

Sheet Журнал_660
A1: Приложение № 7 к Порядку (п. 25) — приказ Министра обороны РФ от 30.10.2015 № 660
A2: ЖУРНАЛ УЧЕТА ВРЕМЕНИ ПРИВЛЕЧЕНИЯ ВОЕННОСЛУЖАЩИХ, ПРОХОДЯЩИХ ВОЕННУЮ СЛУЖБУ ПО КОНТРАКТУ, К ИСПОЛНЕНИЮ ОБЯЗАННОСТЕЙ ВОЕННОЙ СЛУЖБЫ В РАБОЧИЕ ДНИ СВЕРХ УСТАНОВЛЕННОЙ ПРОДОЛЖИТЕЛЬНОСТИ ЕЖЕНЕДЕЛЬНОГО СЛУЖЕБНОГО ВРЕМЕНИ, ПРИВЛЕЧЕНИЯ ЭТИХ ВОЕННОСЛУЖАЩИХ К ИСПОЛНЕНИЮ ОБЯЗАННОСТЕЙ ВОЕННОЙ СЛУЖБЫ В ВЫХОДНЫЕ И ПРАЗДНИЧНЫЕ ДНИ И ПРЕДОСТАВЛЕНИЯ ИМ ДОПОЛНИТЕЛЬНОГО ВРЕМЕНИ ОТДЫХА
A3: на | C3: =Анкета!C16 | D3: неделю | E3: =IFERROR(INDEX(Журнал_день!B$6:B$371,MATCH(C3,Журнал_день!D$6:D$371,0)),"") | H3: =Анкета!C12 | I3: г. | J3: =CONCATENATE(Анкета!C8," в/ч ",Анкета!C9)
A4: № п/п | B4: Воинская должность | C4: Воинское звание | D4: Фамилия, имя, отчество | E4: Учет сверхурочного времени, ч | F4: Учет времени привлечения в выходные и праздничные дни, ч | G4: Суммарное время привлечения к военной службе, ч | H4: Учет предоставления дополнительного времени отдыха | J4: Учет присоединенных дополнительных суток отдыха к отпуску | L4: Учет нереализованного времени отдыха, ч, сут. | M4: Подпись военнослужащего
H5: Дата | I5: Время, ч | J5: Дата | K5: Время, сут.
A7: 1 | B7: 2 | C7: 3 | D7: 4 | E7: 5 | F7: 6 | G7: 7 | H7: 8 | I7: 9 | J7: 10 | K7: 11 | L7: 12 | M7: 13
A8: 1 | B8: =Анкета!C7 | C8: =Анкета!C6 | D8: =Анкета!B19 | E8: =SUMIFS(Журнал_день!I$6:I$371,Журнал_день!D$6:D$371,$C$3) | F8: =SUMIFS(Журнал_день!J$6:J$371,Журнал_день!D$6:D$371,$C$3) | G8: =E8+F8 | I8: =SUMIFS(Журнал_день!K$6:K$371,Журнал_день!D$6:D$371,$C$3) | K8: =SUMIFS(Журнал_день!L$6:L$371,Журнал_день!D$6:D$371,$C$3) | L8: =IF(N8<=0,0,IF(N8<Анкета!C15,N8&" ч",INT(N8/Анкета!C15)&" сут. "&MOD(N8,Анкета!C15)&" ч")) | N8: =SUMIFS(Журнал_день!I$6:I$371,Журнал_день!D$6:D$371,"<="&$C$3)+SUMIFS(Журнал_день!J$6:J$371,Журнал_день!D$6:D$371,"<="&$C$3)-SUMIFS(Журнал_день!K$6:K$371,Журнал_день!D$6:D$371,"<="&$C$3)-SUMIFS(Журнал_день!L$6:L$371,Журнал_день!D$6:D$371,"<="&$C$3)*Анкета!C15
A9: 2 | G9: =IF(OR(E9<>"",F9<>""),N(E9)+N(F9),"")
A10: 3 | G10: =IF(OR(E10<>"",F10<>""),N(E10)+N(F10),"")
A11: 4 | G11: =IF(OR(E11<>"",F11<>""),N(E11)+N(F11),"")
A12: 5 | G12: =IF(OR(E12<>"",F12<>""),N(E12)+N(F12),"")
A13: 6 | G13: =IF(OR(E13<>"",F13<>""),N(E13)+N(F13),"")
A14: 7 | G14: =IF(OR(E14<>"",F14<>""),N(E14)+N(F14),"")
A15: 8 | G15: =IF(OR(E15<>"",F15<>""),N(E15)+N(F15),"")
A16: 9 | G16: =IF(OR(E16<>"",F16<>""),N(E16)+N(F16),"")
A17: 10 | G17: =IF(OR(E17<>"",F17<>""),N(E17)+N(F17),"")
A18: 11 | G18: =IF(OR(E18<>"",F18<>""),N(E18)+N(F18),"")
A19: 12 | G19: =IF(OR(E19<>"",F19<>""),N(E19)+N(F19),"")
A20: 13 | G20: =IF(OR(E20<>"",F20<>""),N(E20)+N(F20),"")
... A23: 16 | G23: =IF(OR(E23<>"",F23<>""),N(E23)+N(F23),"")
A25: Командир (начальник) подразделения | E25: =Анкета!C8
A26: ________________________________________________________________ (воинское звание, подпись, инициал имени, фамилия)
A28: Порядок ведения (приказ МО РФ № 660, приложение № 7): учёт ведётся ЕЖЕНЕДЕЛЬНО. Графы 2–4 — по штатно-должностной книге. Графа 5 — сверхурочка в рабочие дни (часы). Графы 5–7 и 9 — в часах. Графа 11 — в сутках. Графа 12 — в часах, если остаток меньше продолжительности служебного дня, и в сутках, если больше. Записи доводятся до военнослужащих под роспись каждую неделю. Боевое дежурство в эту форму часами не ставьте — оно на листе «БД_сутки».

Sheet БД_сутки
A1: УЧЁТ БОЕВОГО ДЕЖУРСТВА И ИНЫХ МЕРОПРИЯТИЙ БЕЗ ОГРАНИЧЕНИЯ СЛУЖЕБНОГО ВРЕМЕНИ (п. 3 ст. 11 закона № 76-ФЗ, п. 2 Перечня приказа МО РФ № 492)
A2: Время учитывается в СУТКАХ. За каждые трое суток привлечения — двое суток отдыха (п. 5 приложения № 2 к Положению о порядке прохождения военной службы). Эти сутки можно заменить деньгами по рапорту (приказ МО РФ № 80).
A3: Показатель | C3: Значение
A4: Суток боевого дежурства за год (из Журнал_день, колонка «БД») | C4: =SUM(Журнал_день!G6:G371)
A5: Положено суток отдыха (2 за каждые 3) | C5: =INT(C4/3)*2
A6: Остаток суток БД, не вошедших в тройку (не сгорает) | C6: =MOD(C4,3)
A7: Суток суточного наряда за год | C7: =SUM(Журнал_день!H6:H371)
A8: Отдых уже дан, часов (журнал 660, гр. 9) | C8: =SUM(Журнал_день!K6:K371)
A9: Присоединено к отпуску, суток (гр. 11) | C9: =SUM(Журнал_день!L6:L371)
A10: Суток отдыха за БД ещё не использовано | C10: =MAX(0,C5-C9)
A11: Сумма компенсации за неиспользованные сутки БД, руб. | C11: =Анкета!B24*C10
A13: Разбивка по месяцам (нарастающий итог отдыха — с начала года, не помесячно)
A14: Месяц | B14: Суток БД | C14: Наряд, сут. | D14: Сверхурочно, ч | E14: Выходные, ч | F14: БД с начала года | G14: Положено отдыха нарастающим
A15: январь | B15: =SUMIF(Журнал_день!$E$6:$E$371,1,Журнал_день!$G$6:$G$371) | C15: =SUMIF(Журнал_день!$E$6:$E$371,1,Журнал_день!$H$6:$H$371) | D15: =SUMIF(Журнал_день!$E$6:$E$371,1,Журнал_день!$I$6:$I$371) | E15: =SUMIF(Журнал_день!$E$6:$E$371,1,Журнал_день!$J$6:$J$371) | F15: =B15 | G15: =INT(F15/3)*2
A16: февраль | B16: =SUMIF(Журнал_день!$E$6:$E$371,2,Журнал_день!$G$6:$G$371) | C16: =SUMIF(Журнал_день!$E$6:$E$371,2,Журнал_день!$H$6:$H$371) | D16: =SUMIF(Журнал_день!$E$6:$E$371,2,Журнал_день!$I$6:$I$371) | E16: =SUMIF(Журнал_день!$E$6:$E$371,2,Журнал_день!$J$6:$J$371) | F16: =F15+B16 | G16: =INT(F16/3)*2
A17: март | B17: =SUMIF(Журнал_день!$E$6:$E$371,3,Журнал_день!$G$6:$G$371) | C17: =SUMIF(Журнал_день!$E$6:$E$371,3,Журнал_день!$H$6:$H$371) | D17: =SUMIF(Журнал_день!$E$6:$E$371,3,Журнал_день!$I$6:$I$371) | E17: =SUMIF(Журнал_день!$E$6:$E$371,3,Журнал_день!$J$6:$J$371) | F17: =F16+B17 | G17: =INT(F17/3)*2
A18: апрель | B18: =SUMIF(Журнал_день!$E$6:$E$371,4,Журнал_день!$G$6:$G$371) | C18: =SUMIF(Журнал_день!$E$6:$E$371,4,Журнал_день!$H$6:$H$371) | D18: =SUMIF(Журнал_день!$E$6:$E$371,4,Журнал_день!$I$6:$I$371) | E18: =SUMIF(Журнал_день!$E$6:$E$371,4,Журнал_день!$J$6:$J$371) | F18: =F17+B18 | G18: =INT(F18/3)*2
A19: май | B19: =SUMIF(Журнал_день!$E$6:$E$371,5,Журнал_день!$G$6:$G$371) | C19: =SUMIF(Журнал_день!$E$6:$E$371,5,Журнал_день!$H$6:$H$371) | D19: =SUMIF(Журнал_день!$E$6:$E$371,5,Журнал_день!$I$6:$I$371) | E19: =SUMIF(Журнал_день!$E$6:$E$371,5,Журнал_день!$J$6:$J$371) | F19: =F18+B19 | G19: =INT(F19/3)*2
A20: июнь | B20: =SUMIF(Журнал_день!$E$6:$E$371,6,Журнал_день!$G$6:$G$371) | C20: =SUMIF(Журнал_день!$E$6:$E$371,6,Журнал_день!$H$6:$H$371) | D20: =SUMIF(Журнал_день!$E$6:$E$371,6,Журнал_день!$I$6:$I$371) | E20: =SUMIF(Журнал_день!$E$6:$E$371,6,Журнал_день!$J$6:$J$371) | F20: =F19+B20 | G20: =INT(F20/3)*2
A21: июль | B21: =SUMIF(Журнал_день!$E$6:$E$371,7,Журнал_день!$G$6:$G$371) | C21: =SUMIF(Журнал_день!$E$6:$E$371,7,Журнал_день!$H$6:$H$371) | D21: =SUMIF(Журнал_день!$E$6:$E$371,7,Журнал_день!$I$6:$I$371) | E21: =SUMIF(Журнал_день!$E$6:$E$371,7,Журнал_день!$J$6:$J$371) | F21: =F20+B21 | G21: =INT(F21/3)*2
A22: август | B22: =SUMIF(Журнал_день!$E$6:$E$371,8,Журнал_день!$G$6:$G$371) | C22: =SUMIF(Журнал_день!$E$6:$E$371,8,Журнал_день!$H$6:$H$371) | D22: =SUMIF(Журнал_день!$E$6:$E$371,8,Журнал_день!$I$6:$I$371) | E22: =SUMIF(Журнал_день!$E$6:$E$371,8,Журнал_день!$J$6:$J$371) | F22: =F21+B22 | G22: =INT(F22/3)*2
A23: сентябрь | B23: =SUMIF(Журнал_день!$E$6:$E$371,9,Журнал_день!$G$6:$G$371) | C23: =SUMIF(Журнал_день!$E$6:$E$371,9,Журнал_день!$H$6:$H$371) | D23: =SUMIF(Журнал_день!$E$6:$E$371,9,Журнал_день!$I$6:$I$371) | E23: =SUMIF(Журнал_день!$E$6:$E$371,9,Журнал_день!$J$6:$J$371) | F23: =F22+B23 | G23: =INT(F23/3)*2
A24: октябрь | B24: =SUMIF(Журнал_день!$E$6:$E$371,10,Журнал_день!$G$6:$G$371) | C24: =SUMIF(Журнал_день!$E$6:$E$371,10,Журнал_день!$H$6:$H$371) | D24: =SUMIF(Журнал_день!$E$6:$E$371,10,Журнал_день!$I$6:$I$371) | E24: =SUMIF(Журнал_день!$E$6:$E$371,10,Журнал_день!$J$6:$J$371) | F24: =F23+B24 | G24: =INT(F24/3)*2
A25: ноябрь | B25: =SUMIF(Журнал_день!$E$6:$E$371,11,Журнал_день!$G$6:$G$371) | C25: =SUMIF(Журнал_день!$E$6:$E$371,11,Журнал_день!$H$6:$H$371) | D25: =SUMIF(Журнал_день!$E$6:$E$371,11,Журнал_день!$I$6:$I$371) | E25: =SUMIF(Журнал_день!$E$6:$E$371,11,Журнал_день!$J$6:$J$371) | F25: =F24+B25 | G25: =INT(F25/3)*2
A26: декабрь | B26: =SUMIF(Журнал_день!$E$6:$E$371,12,Журнал_день!$G$6:$G$371) | C26: =SUMIF(Журнал_день!$E$6:$E$371,12,Журнал_день!$H$6:$H$371) | D26: =SUMIF(Журнал_день!$E$6:$E$371,12,Журнал_день!$I$6:$I$371) | E26: =SUMIF(Журнал_день!$E$6:$E$371,12,Журнал_день!$J$6:$J$371) | F26: =F25+B26 | G26: =INT(F26/3)*2
A27: ИТОГО за год | B27: =SUM(B15:B26) | C27: =SUM(C15:C26) | D27: =SUM(D15:D26) | E27: =SUM(E15:E26) | F27: =F26 | G27: =G26
A29: Почему отдых не считают отдельно за январь и за февраль: остаток тройки переходит. 2 суток БД в январе + 1 сутки в феврале = 2 суток отдыха, а не ноль.

Sheet Итоги
A1: ИТОГИ ЗА ДЕНЬ, МЕСЯЦ И ГОД
A3: Дата, которую смотрим (за день) | C3: =DATE(Анкета!C12,1,1) | D3: ← поменяйте дату в жёлтой ячейке
A5: Этот день — боевое дежурство? | C5: =IFERROR(IF(SUMIFS(Журнал_день!G$6:G$371,Журнал_день!B$6:B$371,C3)>=1,"да","нет"),"—")
A6: Этот день — суточный наряд? | C6: =IFERROR(IF(SUMIFS(Журнал_день!H$6:H$371,Журнал_день!B$6:B$371,C3)>=1,"да","нет"),"—")
A7: Сверхурочно в этот день, ч | C7: =IFERROR(SUMIFS(Журнал_день!I$6:I$371,Журнал_день!B$6:B$371,C3),0)
A8: Выходной/праздник в этот день, ч | C8: =IFERROR(SUMIFS(Журнал_день!J$6:J$371,Журнал_день!B$6:B$371,C3),0)
A9: Суток БД с 1 января по эту дату | C9: =SUMIFS(Журнал_день!G$6:G$371,Журнал_день!B$6:B$371,"<="&C3,Журнал_день!B$6:B$371,">="&DATE(Анкета!C12,1,1))
A10: Положено суток отдыха на эту дату | C10: =INT(C9/3)*2
A11: Месяц выбранной даты | C11: =CHOOSE(MONTH(C3),"январь","февраль","март","апрель","май","июнь","июль","август","сентябрь","октябрь","ноябрь","декабрь")
A13: За год (для рапорта)
A14: Суток БД за год | C14: =БД_сутки!C4
A15: Положено суток отдыха за БД | C15: =БД_сутки!C5
A16: Уже присоединено к отпуску, сут. | C16: =БД_сутки!C9
A17: К выплате / неиспользовано, сут. | C17: =БД_сутки!C10
A18: Сумма компенсации, руб. | C18: =БД_сутки!C11
A19: Сверхурочно за год, ч (журнал 660) | C19: =БД_сутки!D27
A20: Выходные/праздники за год, ч | C20: =БД_сутки!E27
A21: Наряд за год, сут. (деньги по закону обычно не положены) | C21: =БД_сутки!C7
A23: Денежная компенсация в рапорте берётся из строки «К выплате». Сверхурочка и наряд из журнала 660 компенсируются отдыхом, а не деньгами (п. 1 ст. 11 закона № 76-ФЗ). Если часть отгулов уже брали — укажите их в Журнал_день в колонке «К отпуску, сут».

Sheet Рапорт
A1: РАПОРТ — лист готов к печати. Фамилия подставляется из анкеты.
D3: =Анкета!B21
D5: =Анкета!B22
A8: РАПОРТ
A10: =CONCATENATE("Докладываю, что в период с 01.01.",Анкета!C12," по 31.12.",Анкета!C12," я, ",Анкета!C6," ",Анкета!B19,", привлекался к боевому дежурству (боевой службе), проводимому без ограничения общей продолжительности еженедельного служебного времени.")
A14: =CONCATENATE("Количество суток привлечения к боевому дежурству — ",БД_сутки!C4," суток. Согласно пункту 5 приложения № 2 к Положению о порядке прохождения военной службы за каждые трое суток привлечения положено двое суток отдыха.")
A17: =CONCATENATE("Расчёт: ",БД_сутки!C4," ÷ 3 × 2 = ",БД_сутки!C5," дополнительных суток отдыха. Из них предоставлено (присоединено к отпуску): ",БД_сутки!C9," суток. Остаток, не использованный в виде отдыха: ",БД_сутки!C10," суток.")
A20: =CONCATENATE("В соответствии с пунктом 3 статьи 11 Федерального закона от 27.05.1998 № 76-ФЗ «О статусе военнослужащих» и приказом Министра обороны Российской Федерации от 14.02.2010 № 80 прошу вместо предоставления указанных дополнительных суток отдыха выплатить мне, ",Анкета!C6,"у ",Анкета!B20,", денежную компенсацию за ",БД_сутки!C10," суток.")
A24: =CONCATENATE("Оклад по воинской должности: ",Анкета!C13," руб. Оклад по воинскому званию: ",Анкета!C14," руб. Расчёт компенсации: (",Анкета!C13," + ",Анкета!C14,") ÷ 30 × ",БД_сутки!C10," = ",БД_сутки!C11," руб.")
A27: Дополнительные сутки отдыха за указанный период, кроме отражённых в расчёте, мне не предоставлялись. Расчёт составлен по журналу учёта служебного времени (приказ МО РФ от 30.10.2015 № 660, приложение № 7) и отметкам о боевом дежурстве.
A30: Приложения: 1. Выписка (копия) из журнала учёта служебного времени (приложение № 7 к приказу МО РФ № 660). 2. Расчёт дополнительных суток отдыха за боевое дежурство.
A34: =CONCATENATE("« » ______________ ",Анкета!C12," г.") | D34: =CONCATENATE("__________ / ",Анкета!C6," ",Анкета!B19," /")
A37: Служебная отметка канцелярии: входящий № ________ от « » ______________ 20 г.
